<?xml version="1.0" ?>
<!-- =================================================================================== -->
<!-- |    This document was autogenerated by xacro from ball_beam.xacro                | -->
<!-- |    EDITING THIS FILE BY HAND IS NOT RECOMMENDED                                 | -->
<!-- =================================================================================== -->
<robot name="simplebean">
  <material name="black">
    <color rgba="0 0 0 1"/>
  </material>
  <material name="blue">
    <color rgba="0.6 0.7 0.8 1"/>
  </material>
  <!--Bottom
    plane-->
  <link name="base_link">
    <visual>
      <geometry>
        <box size="1 1 0.02"/>
      </geometry>
      <material name="blue"/>
    </visual>
    <collision>
      <geometry>
        <box size="1 1 0.02"/>
      </geometry>
      <material name="blue"/>
    </collision>
    <inertial>
      <origin rpy="0 0 0" xyz="0 0 0"/>
      <mass value="1"/>
      <inertia ixx="0.08336666666666666" ixy="0" ixz="0" iyy="0.16666666666666666" iyz="0" izz="0.08336666666666666"/>
    </inertial>
  </link>
  <!-- Left Rod -->
  <link name="left_rod">
    <visual>
      <geometry>
        <box size="0.03 0.1 0.5"/>
      </geometry>
      <origin rpy="0 0 0"/>
    </visual>
    <collision>
      <geometry>
        <box size="0.03 0.1 0.5"/>
      </geometry>
      <origin rpy="0 0 0"/>
    </collision>
    <inertial>
      <origin rpy="0 0 0" xyz="0 0 0"/>
      <mass value="1"/>
      <inertia ixx="0.0009083333333333335" ixy="0" ixz="0" iyy="0.021666666666666667" iyz="0" izz="0.020908333333333334"/>
    </inertial>
  </link>
  <joint name="base_to_left_rod" type="fixed">
    <parent link="base_link"/>
    <child link="left_rod"/>
    <origin xyz="-0.40 0 0.1"/>
  </joint>
  <!-- Left Hinge -->
  <link name="left_hinge">
    <visual>
      <geometry>
        <box size="0.15 0.02 0.02"/>
      </geometry>
      <origin rpy="0 0 1.57075" xyz="0 0 0 "/>
      <material name="blue"/>
    </visual>
    <inertial>
      <origin rpy="0 0 1.57075" xyz="0 0 0 "/>
      <mass value="1"/>
      <inertia ixx="6.666666666666667e-05" ixy="0" ixz="0" iyy="0.0019083333333333333" iyz="0" izz="0.0019083333333333333"/>
    </inertial>
  </link>
  <joint name="rod_to_left_hinge" type="revolute">
    <parent link="left_rod"/>
    <child link="left_hinge"/>
    <axis xyz="0 1 0"/>
    <origin xyz="0 0 0.2"/>
    <limit effort="100" lower="-0.5" upper="0.5" velocity="100"/>
  </joint>
  <!-- Center Beam -->
  <link name="center_beam">
    <visual>
      <geometry>
        <box size="0.02 0.1 0.75"/>
      </geometry>
      <origin rpy="0 1.57075 0" xyz="0.32 0 -0.1 "/>
    </visual>
    <collision>
      <geometry>
        <box size="0.02 0.1 0.75"/>
      </geometry>
      <origin rpy="0 1.57075 0" xyz="0.32 0 -0.1 "/>
    </collision>
    <inertial>
      <origin rpy="0 1.57075 0" xyz="0.32 0 -0.1 "/>
      <mass value="1"/>
      <inertia ixx="0.04688333333333333" ixy="0" ixz="0" iyy="4.1666666666666665e-05" iyz="0" izz="0.04690833333333333"/>
    </inertial>
  </link>
  <joint name="hinge_to_center_beam" type="continuous">
    <parent link="left_hinge"/>
    <child link="center_beam"/>
    <axis xyz="0 1 0"/>
    <origin xyz="0 0 .1"/>
  </joint>
</robot>

